#usda 1.0
(
    customLayerData = {
        dictionary cameraSettings = {
            dictionary Front = {
                double3 position = (5, 0, 0)
                double radius = 5
            }
            dictionary Perspective = {
                double3 position = (5.003947655368472, -1.9398383877667027, 4.071541286992596)
                double3 target = (-0.0000036135257550640176, 0.000007544124470904023, 0.000008658511799097823)
            }
            dictionary Right = {
                double3 position = (0, -5, 0)
                double radius = 5
            }
            dictionary Top = {
                double3 position = (0, 0, 5)
                double radius = 5
            }
            string boundCamera = "/OmniverseKit_Persp"
        }
        dictionary omni_layer = {
            string authoring_layer = "./crab_simple.usda"
            dictionary locked = {
            }
            dictionary muteness = {
            }
        }
        dictionary renderSettings = {
        }
    }
    defaultPrim = "World"
    endTimeCode = 1000000
    metersPerUnit = 1
    startTimeCode = 0
    timeCodesPerSecond = 60
    upAxis = "Z"
)

def Xform "World"
{
    def PhysicsScene "PhysicsScene" (
        prepend apiSchemas = ["PhysxSceneAPI"]
    )
    {
        vector3f physics:gravityDirection = (0, 0, 0)
        uniform token physxScene:broadphaseType = "MBP"
        bool physxScene:enableGPUDynamics = 0
    }

    def Xform "GroundPlane"
    {
        quatf xformOp:orient = (1, 0, 0, 0)
        float3 xformOp:scale = (1, 1, 1)
        double3 xformOp:translate = (0, 0, 0)
        uniform token[] xformOpOrder = ["xformOp:translate", "xformOp:orient", "xformOp:scale"]

        def Mesh "CollisionMesh"
        {
            uniform bool doubleSided = 0
            int[] faceVertexCounts = [4]
            int[] faceVertexIndices = [0, 1, 2, 3]
            normal3f[] normals = [(0, 0, 1), (0, 0, 1), (0, 0, 1), (0, 0, 1)]
            point3f[] points = [(-25, -25, 0), (25, -25, 0), (25, 25, 0), (-25, 25, 0)]
            color3f[] primvars:displayColor = [(0.5, 0.5, 0.5)]
            texCoord2f[] primvars:st = [(0, 0), (1, 0), (1, 1), (0, 1)] (
                interpolation = "varying"
            )
            quatf xformOp:orient = (1, 0, 0, 0)
            float3 xformOp:scale = (1, 1, 1)
            double3 xformOp:translate = (0, 1.7833524788354762, 0)
            uniform token[] xformOpOrder = ["xformOp:translate", "xformOp:orient", "xformOp:scale"]
        }

        def Plane "CollisionPlane" (
            prepend apiSchemas = ["PhysicsCollisionAPI"]
        )
        {
            uniform token axis = "Z"
            uniform token purpose = "guide"
        }
    }

    def SphereLight "SphereLight" (
        prepend apiSchemas = ["ShapingAPI"]
    )
    {
        float3[] extent = [(-50, -50, -50), (50, 50, 50)]
        color3f inputs:color = (0.5, 1, 0.5)
        float inputs:intensity = 1000000
        float inputs:radius = 0.1
        float inputs:shaping:cone:angle = 45
        float inputs:shaping:cone:softness = 0.1
        float inputs:shaping:focus
        color3f inputs:shaping:focusTint
        asset inputs:shaping:ies:file
        quatd xformOp:orient = (0.9392052823774539, 0.16881523910203375, -0.04029488237251362, -0.2962620040703764)
        double3 xformOp:scale = (1, 1, 1)
        double3 xformOp:translate = (-0.5276971940893591, 0.027569798479977203, 6.631582252398207)
        uniform token[] xformOpOrder = ["xformOp:translate", "xformOp:orient", "xformOp:scale"]
    }

    def DistantLight "defaultLight" (
        prepend apiSchemas = ["ShapingAPI"]
    )
    {
        float inputs:angle = 1
        float inputs:intensity = 0
        float inputs:shaping:cone:angle = 180
        float inputs:shaping:cone:softness
        float inputs:shaping:focus
        color3f inputs:shaping:focusTint
        asset inputs:shaping:ies:file
        quatd xformOp:orient = (0.6532814824381883, 0.2705980500730985, 0.27059805007309845, 0.6532814824381882)
        double3 xformOp:scale = (1, 1, 1)
        double3 xformOp:translate = (0, 0, 0)
        uniform token[] xformOpOrder = ["xformOp:translate", "xformOp:orient", "xformOp:scale"]
    }
}

def "Render" (
    hide_in_stage_window = true
    no_delete = true
)
{
    def "OmniverseKit"
    {
        def "HydraTextures" (
            hide_in_stage_window = true
            no_delete = true
        )
        {
            def RenderProduct "omni_kit_widget_viewport_ViewportTexture_0" (
                prepend apiSchemas = ["OmniRtxSettingsCommonAdvancedAPI_1", "OmniRtxSettingsRtAdvancedAPI_1", "OmniRtxSettingsPtAdvancedAPI_1", "OmniRtxPostColorGradingAPI_1", "OmniRtxPostChromaticAberrationAPI_1", "OmniRtxPostBloomPhysicalAPI_1", "OmniRtxPostMatteObjectAPI_1", "OmniRtxPostCompositingAPI_1", "OmniRtxPostDofAPI_1", "OmniRtxPostMotionBlurAPI_1", "OmniRtxPostTvNoiseAPI_1", "OmniRtxPostTonemapIrayReinhardAPI_1", "OmniRtxPostDebugSettingsAPI_1", "OmniRtxDebugSettingsAPI_1"]
                hide_in_stage_window = true
                no_delete = true
            )
            {
                rel camera = </OmniverseKit_Persp>
                token omni:rtx:background:source:texture:textureMode = "repeatMirrored"
                token omni:rtx:background:source:type = "domeLight"
                bool omni:rtx:dlss:frameGeneration = 0
                bool omni:rtx:material:db:nonVisualMaterialCSV:enabled = 0
                bool omni:rtx:material:db:syncLoads = 1
                token omni:rtx:post:dlss:execMode = "performance"
                bool omni:rtx:post:registeredCompositing:invertColorCorrection = 1
                bool omni:rtx:post:registeredCompositing:invertToneMap = 1
                bool omni:rtx:pt:lightcache:cached:dontResolveConflicts = 1
                int omni:rtx:pt:maxSamplesPerLaunch = 2073600
                int omni:rtx:pt:mgpu:maxPixelsPerRegionExponent = 12
                token omni:rtx:rendermode
                color3f omni:rtx:rt:ambientLight:color = (0.1, 0.1, 0.1)
                bool omni:rtx:rt:demoire = 0
                bool omni:rtx:rt:ecoMode:enabled
                bool omni:rtx:rt:lightcache:spatialCache:dontResolveConflicts = 1
                bool omni:rtx:scene:hydra:materialSyncLoads = 1
                bool omni:rtx:scene:hydra:mdlMaterialWarmup = 1
                uint omni:rtx:viewTile:limit = 4294967295
                rel orderedVars = </Render/Vars/LdrColor>
                custom bool overrideClipRange = 0
                uniform int2 resolution = (1280, 720)
            }
        }
    }

    def RenderSettings "OmniverseGlobalRenderSettings" (
        prepend apiSchemas = ["OmniRtxSettingsGlobalRtAdvancedAPI_1", "OmniRtxSettingsGlobalPtAdvancedAPI_1"]
        no_delete = true
    )
    {
        rel products = </Render/OmniverseKit/HydraTextures/omni_kit_widget_viewport_ViewportTexture_0>
    }

    def "Vars"
    {
        def RenderVar "LdrColor" (
            hide_in_stage_window = true
            no_delete = true
        )
        {
            uniform string sourceName = "LdrColor"
        }
    }
}

def Xform "krabby" (
    delete apiSchemas = ["PhysicsArticulationRootAPI", "PhysxArticulationAPI"]
    prepend apiSchemas = ["PhysicsArticulationRootAPI", "PhysxArticulationAPI"]
)
{
    quatd xformOp:orient = (1, 0, 0, 0)
    double3 xformOp:scale = (1, 1, 1)
    double3 xformOp:translate = (0, 0, 1)
    uniform token[] xformOpOrder = ["xformOp:translate", "xformOp:orient", "xformOp:scale"]

    def Xform "Leg_FL"
    {
        quatd xformOp:orient = (1, 0, 0, 0)
        double3 xformOp:scale = (1, 1, 1)
        double3 xformOp:translate = (0, 0, 0)
        uniform token[] xformOpOrder = ["xformOp:translate", "xformOp:orient", "xformOp:scale"]

        def Cube "FL_Femur" (
            prepend apiSchemas = ["MaterialBindingAPI", "PhysicsRigidBodyAPI", "PhysxRigidBodyAPI", "PhysicsCollisionAPI", "PhysxCollisionAPI"]
        )
        {
            float3[] extent = [(-0.5, -0.5, -0.5), (0.5, 0.5, 0.5)]
            rel material:binding = </krabby/PlyWood> (
                bindMaterialAs = "weakerThanDescendants"
            )
            bool physics:collisionEnabled = 1
            bool physics:kinematicEnabled = 0
            bool physics:rigidBodyEnabled = 1
            double size = 1
            quatd xformOp:orient = (1, 0, 0, 0)
            double3 xformOp:scale = (0.02, 0.686, 0.127)
            double3 xformOp:translate = (-0.365, -0.959503718539794, -0.182723455627554)
            uniform token[] xformOpOrder = ["xformOp:translate", "xformOp:orient", "xformOp:scale"]
        }

        def Cube "FL_Tibia" (
            prepend apiSchemas = ["MaterialBindingAPI", "PhysicsRigidBodyAPI", "PhysxRigidBodyAPI", "PhysicsCollisionAPI", "PhysxCollisionAPI"]
        )
        {
            float3[] extent = [(-0.5, -0.5, -0.5), (0.5, 0.5, 0.5)]
            rel material:binding = </krabby/PlyWood> (
                bindMaterialAs = "weakerThanDescendants"
            )
            bool physics:collisionEnabled = 1
            bool physics:kinematicEnabled = 0
            bool physics:rigidBodyEnabled = 1
            double size = 1
            quatd xformOp:orient = (1, 0, 0, 0)
            double3 xformOp:scale = (0.02, 0.051, 0.8128)
            double3 xformOp:translate = (-0.3550000000000001, -1.2822536992936961, -0.5286872651520514)
            uniform token[] xformOpOrder = ["xformOp:translate", "xformOp:orient", "xformOp:scale"]
        }

        def Cube "FL_Hip" (
            prepend apiSchemas = ["PhysicsRigidBodyAPI", "PhysxRigidBodyAPI", "PhysicsCollisionAPI", "PhysxCollisionAPI", "MaterialBindingAPI"]
        )
        {
            float3[] extent = [(-0.5, -0.5, -0.5), (0.5, 0.5, 0.5)]
            rel material:binding = </krabby/PlyWood> (
                bindMaterialAs = "weakerThanDescendants"
            )
            bool physics:collisionEnabled = 1
            bool physics:kinematicEnabled = 0
            bool physics:rigidBodyEnabled = 1
            double size = 1
            quatd xformOp:orient = (1, 0, 0, 0)
            double3 xformOp:scale = (0.02, 0.127, 0.61)
            double3 xformOp:translate = (-0.355, -0.678, 0.05)
            uniform token[] xformOpOrder = ["xformOp:translate", "xformOp:orient", "xformOp:scale"]
        }
    }

    def Material "PlyWood" (
        prepend apiSchemas = ["PhysicsMaterialAPI"]
    )
    {
        float physics:dynamicFriction = 0.35
        float physics:restitution = 0.1
        float physics:staticFriction = 0.45
    }

    def Scope "Joints"
    {
        def PhysicsRevoluteJoint "FL_Body_Hip_RevoluteJoint" (
            prepend apiSchemas = ["PhysicsDriveAPI:angular"]
        )
        {
            float drive:angular:physics:damping = 100000
            float drive:angular:physics:stiffness = 1e15
            uniform token physics:axis = "Z"
            rel physics:body0 = </krabby/body>
            rel physics:body1 = </krabby/Leg_FL/FL_Hip>
            float physics:breakForce = 3.4028235e38
            float physics:breakTorque = 3.4028235e38
            bool physics:collisionEnabled = 1
            point3f physics:localPos0 = (-0.49929675, -0.52, 0.2)
            point3f physics:localPos1 = (0, 0.4, 0)
            quatf physics:localRot0 = (1, 0, 0, 0)
            quatf physics:localRot1 = (1, 0, 0, 0)
        }

        def PhysicsRevoluteJoint "FL_Hip_Femur_RevoluteJoint" (
            prepend apiSchemas = ["PhysicsDriveAPI:angular"]
        )
        {
            float drive:angular:physics:damping = 100000
            float drive:angular:physics:stiffness = 1e15
            uniform token physics:axis = "X"
            rel physics:body0 = </krabby/Leg_FL/FL_Hip>
            rel physics:body1 = </krabby/Leg_FL/FL_Femur>
            float physics:breakForce = 3.4028235e38
            float physics:breakTorque = 3.4028235e38
            point3f physics:localPos0 = (-0.5, 0, -0.38151386)
            point3f physics:localPos1 = (0, 0.4, 0)
            quatf physics:localRot0 = (1, 0, 0, 0)
            quatf physics:localRot1 = (1, 0, 0, 0)
        }

        def PhysicsRevoluteJoint "FL_Femur_Tibia_RevoluteJoint" (
            prepend apiSchemas = ["PhysicsDriveAPI:angular"]
        )
        {
            float drive:angular:physics:damping = 100000
            float drive:angular:physics:stiffness = 1e15
            uniform token physics:axis = "X"
            rel physics:body0 = </krabby/Leg_FL/FL_Femur>
            rel physics:body1 = </krabby/Leg_FL/FL_Tibia>
            float physics:breakForce = 3.4028235e38
            float physics:breakTorque = 3.4028235e38
            point3f physics:localPos0 = (0.5, -0.470481, -0.1)
            point3f physics:localPos1 = (0, 0, 0.4)
            quatf physics:localRot0 = (1, 0, 0, 0)
            quatf physics:localRot1 = (1, 0, 0, 0)
        }
    }

    def Cube "body" (
        prepend apiSchemas = ["PhysicsRigidBodyAPI", "PhysxRigidBodyAPI", "PhysicsCollisionAPI", "PhysxCollisionAPI", "MaterialBindingAPI"]
    )
    {
        float3[] extent = [(-0.5, -0.5, -0.5), (0.5, 0.5, 0.5)]
        rel material:binding = </krabby/PlyWood> (
            bindMaterialAs = "weakerThanDescendants"
        )
        bool physics:collisionEnabled = 1
        bool physics:kinematicEnabled = 0
        bool physics:rigidBodyEnabled = 1
        double size = 1
        quatd xformOp:orient = (1, 0, 0, 0)
        double3 xformOp:scale = (0.7110000252723694, 1.218999981880188, 0.25)
        double3 xformOp:translate = (0, 0, 0)
        uniform token[] xformOpOrder = ["xformOp:translate", "xformOp:orient", "xformOp:scale"]
    }

    def Scope "Graphs"
    {
        def OmniGraph "Velocity_Controller"
        {
            token evaluationMode = "Automatic"
            token evaluator:type = "execution"
            token fabricCacheBacking = "StageWithoutHistory"
            int2 fileFormatVersion = (1, 9)
            token pipelineStage = "pipelineStageSimulation"

            def OmniGraphNode "OnPlaybackTick"
            {
                token node:type = "omni.graph.action.OnPlaybackTick"
                int node:typeVersion = 2
                custom double outputs:deltaSeconds
                custom double outputs:frame
                custom uint outputs:tick (
                    customData = {
                        bool isExecution = 1
                    }
                )
                custom double outputs:time
            }

            def OmniGraphNode "JointCommandArray"
            {
                custom int inputs:arraySize = 3
                custom token inputs:arrayType = "double[]" (
                    allowedTokens = ["auto", "bool[]", "double[]", "float[]", "half[]", "int[]", "int64[]", "token[]", "uchar[]", "uint[]", "uint64[]", "double[2][]", "double[3][]", "double[4][]", "matrixd[2][]", "matrixd[3][]", "matrixd[4][]", "float[2][]", "float[3][]", "float[4][]", "half[2][]", "half[3][]", "half[4][]", "int[2][]", "int[3][]", "int[4][]", "timecode[]", "frame[4][]", "colord[3][]", "colorf[3][]", "colorh[3][]", "colord[4][]", "colorf[4][]", "colorh[4][]", "normald[3][]", "normalf[3][]", "normalh[3][]", "pointd[3][]", "pointf[3][]", "pointh[3][]", "quatd[4][]", "quatf[4][]", "quath[4][]", "texcoordd[2][]", "texcoordf[2][]", "texcoordh[2][]", "texcoordd[3][]", "texcoordf[3][]", "texcoordh[3][]", "vectord[3][]", "vectorf[3][]", "vectorh[3][]"]
                )
                custom token inputs:input0 (
                    customData = {
                        dictionary omni = {
                            dictionary graph = {
                                double attrValue = 0
                                string resolvedType = "double"
                            }
                        }
                    }
                )
                custom double inputs:input1 = 0
                custom double inputs:input2 = 0
                token node:type = "omni.graph.nodes.ConstructArray"
                int node:typeVersion = 1
                custom token outputs:array
            }

            def OmniGraphNode "ArticulationController"
            {
                custom double[] inputs:effortCommand
                custom uint inputs:execIn (
                    customData = {
                        bool isExecution = 1
                    }
                )
                prepend uint inputs:execIn.connect = </krabby/Graphs/Velocity_Controller/OnPlaybackTick.outputs:tick>
                custom int[] inputs:jointIndices
                custom token[] inputs:jointNames
                prepend token[] inputs:jointNames.connect = </krabby/Graphs/Velocity_Controller/JointNameArray.outputs:array>
                custom double[] inputs:positionCommand
                custom string inputs:robotPath
                custom rel inputs:targetPrim = </krabby> (
                    customData = {
                        dictionary omni = {
                            dictionary graph = {
                                string relType = "target"
                            }
                        }
                    }
                )
                custom double[] inputs:velocityCommand
                prepend double[] inputs:velocityCommand.connect = </krabby/Graphs/Velocity_Controller/JointCommandArray.outputs:array>
                token node:type = "isaacsim.core.nodes.IsaacArticulationController"
                int node:typeVersion = 1
            }

            def OmniGraphNode "JointNameArray"
            {
                custom int inputs:arraySize = 3
                custom token inputs:arrayType = "token[]" (
                    allowedTokens = ["auto", "bool[]", "double[]", "float[]", "half[]", "int[]", "int64[]", "token[]", "uchar[]", "uint[]", "uint64[]", "double[2][]", "double[3][]", "double[4][]", "matrixd[2][]", "matrixd[3][]", "matrixd[4][]", "float[2][]", "float[3][]", "float[4][]", "half[2][]", "half[3][]", "half[4][]", "int[2][]", "int[3][]", "int[4][]", "timecode[]", "frame[4][]", "colord[3][]", "colorf[3][]", "colorh[3][]", "colord[4][]", "colorf[4][]", "colorh[4][]", "normald[3][]", "normalf[3][]", "normalh[3][]", "pointd[3][]", "pointf[3][]", "pointh[3][]", "quatd[4][]", "quatf[4][]", "quath[4][]", "texcoordd[2][]", "texcoordf[2][]", "texcoordh[2][]", "texcoordd[3][]", "texcoordf[3][]", "texcoordh[3][]", "vectord[3][]", "vectorf[3][]", "vectorh[3][]"]
                )
                custom token inputs:input0 (
                    customData = {
                        dictionary omni = {
                            dictionary graph = {
                                token attrValue = "FL_Body_Hip_RevoluteJoint"
                                string resolvedType = "token"
                            }
                        }
                    }
                )
                custom token inputs:input1 = "FL_Hip_Femur_RevoluteJoint"
                custom token inputs:input2 = "FL_Femur_Tibia_RevoluteJoint"
                token node:type = "omni.graph.nodes.ConstructArray"
                int node:typeVersion = 1
                custom token outputs:array
            }
        }
    }
}

